Workbook

Sheet Dashboard
A1: CS Onboarding Journey Dashboard
A2: 30 / 60 / 90-day program performance - April 2026 cohort
A4: New Hires | C4: 90-Day Completion | E4: Confidence Growth | G4: Readiness Score | I4: Manager Satisfaction | K4: Repeated Qs Reduced
A5: =24 -> 24 | C5: ='KPI Summary'!B8 -> 0.8725 | E5: ='KPI Summary'!B9 & " → " & 'KPI Summary'!B10 -> 3.05 → 4.275 | G5: ='KPI Summary'!B12 -> 4.1375 | I5: ='KPI Summary'!B13 -> 4.35 | K5: ='KPI Summary'!B16 -> 0.3525641
A6: Active in program | C6: Avg. across cohort | E6: Day 30 to Day 90 | G6: Cohort average | I6: Manager-reported | K6: Before vs After
A43: Recommended Actions
A44: 1. Add extra product practice for teams below 80% knowledge score.
A45: 2. Create more customer scenarios for Enterprise CS.
A46: 3. Add a manager calibration session for readiness scoring.
A47: 4. Improve knowledge base navigation.
A48: 5. Review repeated questions monthly.
A59: Chart Data (auto-calculated from Raw Data)
A60: Phase | B60: Completion
A61: 30-Day | B61: =AVERAGE('Raw Data'!E6:E13) -> 0.87375
A62: 60-Day | B62: =AVERAGE('Raw Data'!F6:F13) -> 0.81
A63: 90-Day | B63: =AVERAGE('Raw Data'!G6:G13) -> 0.8725
A66: Phase | B66: Confidence
A67: Day 30 | B67: =AVERAGE('Raw Data'!H6:H13) -> 3.05
A68: Day 60 | B68: =AVERAGE('Raw Data'!I6:I13) -> 3.875
A69: Day 90 | B69: =AVERAGE('Raw Data'!J6:J13) -> 4.275
A71: Team | B71: Knowledge | C71: Readiness
A72: CS SMB | B72: =AVERAGEIF('Raw Data'!B6:B13,"CS SMB",'Raw Data'!B18:B25) -> 0.88666667 | C72: =AVERAGEIF('Raw Data'!B6:B13,"CS SMB",'Raw Data'!C18:C25) -> 4.3333333
A73: CS Enterprise | B73: =AVERAGEIF('Raw Data'!B6:B13,"CS Enterprise",'Raw Data'!B18:B25) -> 0.85333333 | C73: =AVERAGEIF('Raw Data'!B6:B13,"CS Enterprise",'Raw Data'!C18:C25) -> 4.1666667
A74: CS Mid-Market | B74: =AVERAGEIF('Raw Data'!B6:B13,"CS Mid-Market",'Raw Data'!B18:B25) -> 0.795 | C74: =AVERAGEIF('Raw Data'!B6:B13,"CS Mid-Market",'Raw Data'!C18:C25) -> 3.8
A76: Employee | B76: Scenarios %
A77: ="New Hire 1" -> New Hire 1 | B77: ='Raw Data'!F18/4 -> 1
A78: ="New Hire 2" -> New Hire 2 | B78: ='Raw Data'!F19/4 -> 0.75
A79: ="New Hire 3" -> New Hire 3 | B79: ='Raw Data'!F20/4 -> 1
A80: ="New Hire 4" -> New Hire 4 | B80: ='Raw Data'!F21/4 -> 0.75
A81: ="New Hire 5" -> New Hire 5 | B81: ='Raw Data'!F22/4 -> 1
A82: ="New Hire 6" -> New Hire 6 | B82: ='Raw Data'!F23/4 -> 1
A83: ="New Hire 7" -> New Hire 7 | B83: ='Raw Data'!F24/4 -> 0.75
A84: ="New Hire 8" -> New Hire 8 | B84: ='Raw Data'!F25/4 -> 1
A86: Employee | B86: Before | C86: After
A87: New Hire 1 | B87: ='Raw Data'!G18 -> 18 | C87: ='Raw Data'!H18 -> 11
A88: New Hire 2 | B88: ='Raw Data'!G19 -> 22 | C88: ='Raw Data'!H19 -> 15
A89: New Hire 3 | B89: ='Raw Data'!G20 -> 16 | C89: ='Raw Data'!H20 -> 9
A90: New Hire 4 | B90: ='Raw Data'!G21 -> 25 | C90: ='Raw Data'!H21 -> 18
A91: New Hire 5 | B91: ='Raw Data'!G22 -> 20 | C91: ='Raw Data'!H22 -> 13
A92: New Hire 6 | B92: ='Raw Data'!G23 -> 17 | C92: ='Raw Data'!H23 -> 10
...

Sheet KPI Summary
A2: Aggregate measures - calculated from Raw Data
A4: KPI | B4: Result
A5: New Hires in Program | B5: 24
A6: 30-Day Completion Average | B6: =AVERAGE('Raw Data'!E6:E13) -> 0.87375
A7: 60-Day Completion Average | B7: =AVERAGE('Raw Data'!F6:F13) -> 0.81
A8: 90-Day Completion Average | B8: =AVERAGE('Raw Data'!G6:G13) -> 0.8725
A9: Average Confidence at Day 30 | B9: =AVERAGE('Raw Data'!H6:H13) -> 3.05
A10: Average Confidence at Day 90 | B10: =AVERAGE('Raw Data'!J6:J13) -> 4.275
A11: Average Knowledge Score | B11: =AVERAGE('Raw Data'!B18:B25) -> 0.85125
A12: Average Readiness Score | B12: =AVERAGE('Raw Data'!C18:C25) -> 4.1375
A13: Manager Satisfaction | B13: =AVERAGE('Raw Data'!D18:D25) -> 4.35
A14: Shadowing Completion | B14: =AVERAGE('Raw Data'!E18:E25)/5 -> 0.875
A15: Scenario Practice Completion | B15: =AVERAGE('Raw Data'!F18:F25)/4 -> 0.90625
A16: Reduction in Repeated Questions | B16: =(SUM('Raw Data'!G18:G25)-SUM('Raw Data'!H18:H25))/SUM('Raw Data'!G18:G25) -> 0.3525641

Sheet Raw Data
A1: Raw Data
A2: Source data for CS Onboarding Journey Dashboard
A4: A. Core Progress
A5: Employee | B5: Team | C5: Manager | D5: Start | E5: 30-Day | F5: 60-Day | G5: 90-Day | H5: Conf 30 | I5: Conf 60 | J5: Conf 90
A6: New Hire 1 | B6: CS SMB | C6: Manager A | D6: 01.04 | E6: 0.92 | F6: 0.84 | G6: 0.9 | H6: 3.2 | I6: 4 | J6: 4.5
A7: New Hire 2 | B7: CS Enterprise | C7: Manager B | D7: 03.04 | E7: 0.85 | F7: 0.78 | G7: 0.86 | H7: 2.8 | I7: 3.7 | J7: 4.1
A8: New Hire 3 | B8: CS SMB | C8: Manager C | D8: 07.04 | E8: 0.95 | F8: 0.88 | G8: 0.92 | H8: 3.5 | I8: 4.2 | J8: 4.6
A9: New Hire 4 | B9: CS Mid-Market | C9: Manager D | D9: 10.04 | E9: 0.76 | F9: 0.72 | G9: 0.8 | H9: 2.6 | I9: 3.5 | J9: 3.9
A10: New Hire 5 | B10: CS Enterprise | C10: Manager B | D10: 12.04 | E10: 0.88 | F10: 0.81 | G10: 0.87 | H10: 3 | I10: 3.9 | J10: 4.2
A11: New Hire 6 | B11: CS SMB | C11: Manager A | D11: 15.04 | E11: 0.9 | F11: 0.83 | G11: 0.89 | H11: 3.1 | I11: 4 | J11: 4.4
A12: New Hire 7 | B12: CS Mid-Market | C12: Manager D | D12: 18.04 | E12: 0.82 | F12: 0.76 | G12: 0.84 | H12: 2.9 | I12: 3.6 | J12: 4
A13: New Hire 8 | B13: CS Enterprise | C13: Manager E | D13: 20.04 | E13: 0.91 | F13: 0.86 | G13: 0.9 | H13: 3.3 | I13: 4.1 | J13: 4.5
A16: B. Readiness Metrics
A17: Employee | B17: Knowledge | C17: Readiness | D17: Satisfaction | E17: Shadowing | F17: Scenario | G17: Questions Before | H17: Questions After
A18: New Hire 1 | B18: 0.88 | C18: 4.3 | D18: 4.5 | E18: 5 | F18: 4 | G18: 18 | H18: 11
A19: New Hire 2 | B19: 0.82 | C19: 4 | D19: 4.2 | E19: 4 | F19: 3 | G19: 22 | H19: 15
A20: New Hire 3 | B20: 0.91 | C20: 4.5 | D20: 4.7 | E20: 5 | F20: 4 | G20: 16 | H20: 9
A21: New Hire 4 | B21: 0.78 | C21: 3.7 | D21: 4 | E21: 3 | F21: 3 | G21: 25 | H21: 18
A22: New Hire 5 | B22: 0.85 | C22: 4.1 | D22: 4.3 | E22: 4 | F22: 4 | G22: 20 | H22: 13
A23: New Hire 6 | B23: 0.87 | C23: 4.2 | D23: 4.4 | E23: 5 | F23: 4 | G23: 17 | H23: 10
A24: New Hire 7 | B24: 0.81 | C24: 3.9 | D24: 4.1 | E24: 4 | F24: 3 | G24: 23 | H24: 16
A25: New Hire 8 | B25: 0.89 | C25: 4.4 | D25: 4.6 | E25: 5 | F25: 4 | G25: 15 | H25: 9

Sheet Notes & Methodology
A1: Notes & Methodology
A2: How each KPI on this dashboard is calculated
A4: KPI / Item | B4: Source & Formula
A5: New Hires in Program | B5: Hardcoded headcount value (24). Update manually as cohort changes.
A6: 30 / 60 / 90-Day Completion Average | B6: AVERAGE of Raw Data column 30-Day / 60-Day / 90-Day across all employees.
A7: Average Confidence (Day 30 / 90) | B7: AVERAGE of Conf 30 / Conf 90 columns. Scale: 1-5.
A8: Average Knowledge Score | B8: AVERAGE of Raw Data B (Knowledge) column. % correct on knowledge checks.
A9: Average Readiness Score | B9: AVERAGE of Readiness column. Manager-rated 1-5.
A10: Manager Satisfaction | B10: AVERAGE of Satisfaction column - manager-reported on 1-5 scale.
A11: Shadowing Completion | B11: AVERAGE of Shadowing sessions completed / 5 (target).
A12: Scenario Practice Completion | B12: AVERAGE of Scenarios completed / 4 (target).
A13: Reduction in Repeated Questions | B13: (SUM Before - SUM After) / SUM Before, across all employees.
A14: Knowledge / Readiness by Team | B14: AVERAGEIF on team. Teams: CS SMB, CS Enterprise, CS Mid-Market.
A15: Confidence Growth (chart) | B15: Cohort average of Conf 30 / Conf 60 / Conf 90.
... A18: Source | B18: Internal: CS Onboarding tracker, manager scorecards, knowledge base analytics.
